Workbook
Name budget: 'Budget Dashboard'!$L1
Name budget_range: 'Budget Dashboard'!$Q1
Name budget_rank: 'Budget Dashboard'!$R1
Name cc_budget: Calculations!$K1
Name cc_delta: Calculations!$L1
Name cc_in_focus: Calculations!$G1
Name cc_month_number: Calculations!$F1
Name cc_show_remaining_budget: Calculations!$I1
Name cc_show_type: Calculations!$H1
Name cc_tracked: Calculations!$J1
Name cc_type: Calculations!$E1
Name comb_rank: 'Budget Dashboard'!$S1
Name comb_rank_norm: 'Budget Dashboard'!$U1
Name comb_rank_norm_run_range: 'Budget Dashboard'!$V1
Name comb_rank_range: 'Budget Dashboard'!$T1
Name comb_rank_unique: 'Budget Dashboard'!$W1
Name current_date: TODAY()
Name expenses_header_row: ROW(Expenses[[#Headers],[Expenses]])
Name expenses_max_row: MAX(ROW(Expenses[]))
Name expenses_min_row: MIN(ROW(Expenses[]))
Name expenses_total_row: ROW('Budget Planning'!$C$58)
Name header_row_id: 'Budget Dashboard'!$D1
Name income_header_row: ROW(Income[[#Headers],[Income]])
Name income_max_row: MAX(ROW(Income[]))
Name income_min_row: MIN(ROW(Income[]))
Name income_total_row: ROW('Budget Planning'!$C$20)
Name is_cat: 'Budget Dashboard'!$F1
Name is_empty: 'Budget Dashboard'!$H1
Name is_header: 'Budget Dashboard'!$E1
Name is_total: 'Budget Dashboard'!$G1
Name item: 'Budget Dashboard'!$J1
Name out_budget: 'Budget Dashboard'!$AA1
Name out_percentage_completed: 'Budget Dashboard'!$AB1
Name out_tracked: 'Budget Dashboard'!$Z1
Name row_id: 'Budget Dashboard'!$C1
Name savings_header_row: ROW(Savings[[#Headers],[Savings]])
Name savings_max_row: MAX(ROW(Savings[]))
Name savings_min_row: MIN(ROW(Savings[]))
Name savings_rate_calculation_type: Settings!$E$22
Name savings_total_row: ROW('Budget Planning'!$C$71)
Name selected_period: Calculations!$E$20
Name selected_period_display: Calculations!$E$21
Name selected_year: Calculations!$E$19
Name shift_late_income_starting_day: Settings!$E$18
Name shift_late_income_status: Settings!$E$16
Name sort_max_row: 'Budget Dashboard'!$N1
Name sort_min_row: 'Budget Dashboard'!$M1
Name starting_year: Settings!$E$8
Name tracked: 'Budget Dashboard'!$K1
Name tracked_range: 'Budget Dashboard'!$O1
Name tracked_rank: 'Budget Dashboard'!$P1
Name type: 'Budget Dashboard'!$I1

Sheet Settings
B2: Settings
C6: General
D8: Starting Year: | E8: 2022 | G8: Set the starting year (yyyy) once at the beginning and do not change it again.
C12: Budget Tracking & Dashboard
D14: Late Monthly Income
D16: Shift late income: | E16: Inactive | G16: Activate this option to treat late income received on or after a certain day of the month as income for the next month. This is especially recommended in case you receive your monthly paycheck towards the end of the month and prefer to consider this income as the disposable income for the next month.
D18: Starting on day x in month: | E18: 20
D20: KPI Calculation in Dashboard
D22: Savings Rate as % of Income: | E22: % allocated to Savings | G22: Choose how you want the savings rate (SR) to be calculated in the dashboard KPI tiles: 1) Active Option (% allocated to Savings): SR = Savings / Income 2) Passive Option (% not allocated to Expenses): SR = (Income - Expenses) / Income

Sheet Budget Planning
B2: Budget Planning
C5: Define starting year in Settings ➜ | E5: =starting_year -> 2022 | S5: =E5+1 -> 2023 | AG5: =S5+1 -> 2024 | AU5: =AG5+1 -> 2025 | BI5: =AU5+1 -> 2026 | BW5: =BI5+1 -> 2027 | CK5: =BW5+1 -> 2028 | CY5: =CK5+1 -> 2029 | DM5: =CY5+1 -> 2030 | EA5: =DM5+1 -> 2031
E6: =IF(E7=0, "Jan ✓", "Jan") -> Jan ✓ | F6: =IF(F7=0, "Feb ✓", "Feb") -> Feb ✓ | G6: =IF(G7=0, "Mar ✓", "Mar") -> Mar ✓ | H6: =IF(H7=0, "Apr ✓", "Apr") -> Apr ✓ | I6: =IF(I7=0, "May ✓", "May") -> May ✓ | J6: =IF(J7=0, "Jun ✓", "Jun") -> Jun ✓ | K6: =IF(K7=0, "Jul ✓", "Jul") -> Jul ✓ | L6: =IF(L7=0, "Aug ✓", "Aug") -> Aug ✓ | M6: =IF(M7=0, "Sep ✓", "Sep") -> Sep ✓ | N6: =IF(N7=0, "Oct ✓", "Oct") -> Oct ✓ | O6: =IF(O7=0, "Nov ✓", "Nov") -> Nov ✓ | P6: =IF(P7=0, "Dec ✓", "Dec") -> Dec ✓ | Q6: =IF(Q7=0, "Total ✓", "Total") -> Total ✓ | S6: =IF(S7=0, "Jan ✓", "Jan") -> Jan ✓ | T6: =IF(T7=0, "Feb ✓", "Feb") -> Feb ✓ | U6: =IF(U7=0, "Mar ✓", "Mar") -> Mar ✓ | V6: =IF(V7=0, "Apr ✓", "Apr") -> Apr ✓ | W6: =IF(W7=0, "May ✓", "May") -> May ✓ | X6: =IF(X7=0, "Jun ✓", "Jun") -> Jun ✓ | Y6: =IF(Y7=0, "Jul ✓", "Jul") -> Jul ✓ | Z6: =IF(Z7=0, "Aug ✓", "Aug") -> Aug ✓ | AA6: =IF(AA7=0, "Sep ✓", "Sep") -> Sep ✓ | AB6: =IF(AB7=0, "Oct ✓", "Oct") -> Oct ✓ | AC6: =IF(AC7=0, "Nov ✓", "Nov") -> Nov ✓ | AD6: =IF(AD7=0, "Dec ✓", "Dec") -> Dec ✓ | AE6: =IF(AE7=0, "Total ✓", "Total") -> Total ✓ | AG6: =IF(AG7=0, "Jan ✓", "Jan") -> Jan ✓ | AH6: =IF(AH7=0, "Feb ✓", "Feb") -> Feb ✓ | AI6: =IF(AI7=0, "Mar ✓", "Mar") -> Mar ✓ | AJ6: =IF(AJ7=0, "Apr ✓", "Apr") -> Apr ✓ | AK6: =IF(AK7=0, "May ✓", "May") -> May ✓ | AL6: =IF(AL7=0, "Jun ✓", "Jun") -> Jun ✓ | AM6: =IF(AM7=0, "Jul ✓", "Jul") -> Jul ✓ | AN6: =IF(AN7=0, "Aug ✓", "Aug") -> Aug ✓ | AO6: =IF(AO7=0, "Sep ✓", "Sep") -> Sep ✓ | AP6: =IF(AP7=0, "Oct ✓", "Oct") -> Oct ✓ | AQ6: =IF(AQ7=0, "Nov ✓", "Nov") -> Nov ✓ | AR6: =IF(AR7=0, "Dec ✓", "Dec") -> Dec ✓ | AS6: =IF(AS7=0, "Total ✓", "Total") -> Total ✓ | AU6: =IF(AU7=0, "Jan ✓", "Jan") -> Jan ✓ | AV6: =IF(AV7=0, "Feb ✓", "Feb") -> Feb ✓ | AW6: =IF(AW7=0, "Mar ✓", "Mar") -> Mar ✓ | AX6: =IF(AX7=0, "Apr ✓", "Apr") -> Apr ✓ | AY6: =IF(AY7=0, "May ✓", "May") -> May ✓ | AZ6: =IF(AZ7=0, "Jun ✓", "Jun") -> Jun ✓ | BA6: =IF(BA7=0, "Jul ✓", "Jul") -> Jul ✓ | BB6: =IF(BB7=0, "Aug ✓", "Aug") -> Aug ✓ | BC6: =IF(BC7=0, "Sep ✓", "Sep") -> Sep ✓ | BD6: =IF(BD7=0, "Oct ✓", "Oct") -> Oct ✓ | BE6: =IF(BE7=0, "Nov ✓", "Nov") -> Nov ✓ | BF6: =IF(BF7=0, "Dec ✓", "Dec") -> Dec ✓ | BG6: =IF(BG7=0, "Total ✓", "Total") -> Total ✓ | BI6: =IF(BI7=0, "Jan ✓", "Jan") -> Jan ✓ | BJ6: =IF(BJ7=0, "Feb ✓", "Feb") -> Feb ✓ | BK6: =IF(BK7=0, "Mar ✓", "Mar") -> Mar ✓ | BL6: =IF(BL7=0, "Apr ✓", "Apr") -> Apr ✓ | BM6: =IF(BM7=0, "May ✓", "May") -> May ✓ | BN6: =IF(BN7=0, "Jun ✓", "Jun") -> Jun ✓ | BO6: =IF(BO7=0, "Jul ✓", "Jul") -> Jul ✓ | BP6: =IF(BP7=0, "Aug ✓", "Aug") -> Aug ✓ | BQ6: =IF(BQ7=0, "Sep ✓", "Sep") -> Sep ✓ | BR6: =IF(BR7=0, "Oct ✓", "Oct") -> Oct ✓ | BS6: =IF(BS7=0, "Nov ✓", "Nov") -> Nov ✓ | BT6: =IF(BT7=0, "Dec ✓", "Dec") -> Dec ✓ | BU6: =IF(BU7=0, "Total ✓", "Total") -> Total ✓ | BW6: =IF(BW7=0, "Jan ✓", "Jan") -> Jan ✓ | BX6: =IF(BX7=0, "Feb ✓", "Feb") -> Feb ✓ | BY6: =IF(BY7=0, "Mar ✓", "Mar") -> Mar ✓ | BZ6: =IF(BZ7=0, "Apr ✓", "Apr") -> Apr ✓ | CA6: =IF(CA7=0, "May ✓", "May") -> May ✓ | CB6: =IF(CB7=0, "Jun ✓", "Jun") -> Jun ✓ | CC6: =IF(CC7=0, "Jul ✓", "Jul") -> Jul ✓ | CD6: =IF(CD7=0, "Aug ✓", "Aug") -> Aug ✓ | CE6: =IF(CE7=0, "Sep ✓", "Sep") -> Sep ✓ | CF6: =IF(CF7=0, "Oct ✓", "Oct") -> Oct ✓ | CG6: =IF(CG7=0, "Nov ✓", "Nov") -> Nov ✓ | CH6: =IF(CH7=0, "Dec ✓", "Dec") -> Dec ✓ | CI6: =IF(CI7=0, "Total ✓", "Total") -> Total ✓ | CK6: =IF(CK7=0, "Jan ✓", "Jan") -> Jan ✓ | CL6: =IF(CL7=0, "Feb ✓", "Feb") -> Feb ✓ | CM6: =IF(CM7=0, "Mar ✓", "Mar") -> Mar ✓ | CN6: =IF(CN7=0, "Apr ✓", "Apr") -> Apr ✓ | CO6: =IF(CO7=0, "May ✓", "May") -> May ✓ | CP6: =IF(CP7=0, "Jun ✓", "Jun") -> Jun ✓ | CQ6: =IF(CQ7=0, "Jul ✓", "Jul") -> Jul ✓ | CR6: =IF(CR7=0, "Aug ✓", "Aug") -> Aug ✓ | CS6: =IF(CS7=0, "Sep ✓", "Sep") -> Sep ✓ | CT6: =IF(CT7=0, "Oct ✓", "Oct") -> Oct ✓ | CU6: =IF(CU7=0, "Nov ✓", "Nov") -> Nov ✓ | CV6: =IF(CV7=0, "Dec ✓", "Dec") -> Dec ✓ | CW6: =IF(CW7=0, "Total ✓", "Total") -> Total ✓ | CY6: =IF(CY7=0, "Jan ✓", "Jan") -> Jan ✓ | CZ6: =IF(CZ7=0, "Feb ✓", "Feb") -> Feb ✓ | DA6: =IF(DA7=0, "Mar ✓", "Mar") -> Mar ✓ | DB6: =IF(DB7=0, "Apr ✓", "Apr") -> Apr ✓ | DC6: =IF(DC7=0, "May ✓", "May") -> May ✓ | DD6: =IF(DD7=0, "Jun ✓", "Jun") -> Jun ✓ | DE6: =IF(DE7=0, "Jul ✓", "Jul") -> Jul ✓ | DF6: =IF(DF7=0, "Aug ✓", "Aug") -> Aug ✓ | DG6: =IF(DG7=0, "Sep ✓", "Sep") -> Sep ✓ | DH6: =IF(DH7=0, "Oct ✓", "Oct") -> Oct ✓ | DI6: =IF(DI7=0, "Nov ✓", "Nov") -> Nov ✓ | DJ6: =IF(DJ7=0, "Dec ✓", "Dec") -> Dec ✓ | DK6: =IF(DK7=0, "Total ✓", "Total") -> Total ✓ | DM6: =IF(DM7=0, "Jan ✓", "Jan") -> Jan ✓ | DN6: =IF(DN7=0, "Feb ✓", "Feb") -> Feb ✓ | DO6: =IF(DO7=0, "Mar ✓", "Mar") -> Mar ✓ | DP6: =IF(DP7=0, "Apr ✓", "Apr") -> Apr ✓ | DQ6: =IF(DQ7=0, "May ✓", "May") -> May ✓ | DR6: =IF(DR7=0, "Jun ✓", "Jun") -> Jun ✓ | DS6: =IF(DS7=0, "Jul ✓", "Jul") -> Jul ✓ | DT6: =IF(DT7=0, "Aug ✓", "Aug") -> Aug ✓ | DU6: =IF(DU7=0, "Sep ✓", "Sep") -> Sep ✓ | DV6: =IF(DV7=0, "Oct ✓", "Oct") -> Oct ✓ | DW6: =IF(DW7=0, "Nov ✓", "Nov") -> Nov ✓ | DX6: =IF(DX7=0, "Dec ✓", "Dec") -> Dec ✓ | DY6: =IF(DY7=0, "Total ✓", "Total") -> Total ✓ | EA6: =IF(EA7=0, "Jan ✓", "Jan") -> Jan ✓ | EB6: =IF(EB7=0, "Feb ✓", "Feb") -> Feb ✓ | EC6: =IF(EC7=0, "Mar ✓", "Mar") -> Mar ✓ | ED6: =IF(ED7=0, "Apr ✓", "Apr") -> Apr ✓ | EE6: =IF(EE7=0, "May ✓", "May") -> May ✓ | EF6: =IF(EF7=0, "Jun ✓", "Jun") -> Jun ✓ | EG6: =IF(EG7=0, "Jul ✓", "Jul") -> Jul ✓ | EH6: =IF(EH7=0, "Aug ✓", "Aug") -> Aug ✓ | EI6: =IF(EI7=0, "Sep ✓", "Sep") -> Sep ✓ | EJ6: =IF(EJ7=0, "Oct ✓", "Oct") -> Oct ✓ | EK6: =IF(EK7=0, "Nov ✓", "Nov") -> Nov ✓ | EL6: =IF(EL7=0, "Dec ✓", "Dec") -> Dec ✓ | EM6: =IF(EM7=0, "Total ✓", "Total") -> Total ✓
C7: To be allocated: | E7: =E20-(E58+E71) -> 0 | F7: =F20-(F58+F71) -> 0 | G7: =G20-(G58+G71) -> 0 | H7: =H20-(H58+H71) -> 0 | I7: =I20-(I58+I71) -> 0 | J7: =J20-(J58+J71) -> 0 | K7: =K20-(K58+K71) -> 0 | L7: =L20-(L58+L71) -> 0 | ... Q7: =Q20-(Q58+Q71) -> 0 | S7: =S20-(S58+S71) -> 0 | T7: =T20-(T58+T71) -> 0 | U7: =U20-(U58+U71) -> 0 | V7: =V20-(V58+V71) -> 0 | W7: =W20-(W58+W71) -> 0 | X7: =X20-(X58+X71) -> 0 | Y7: =Y20-(Y58+Y71) -> 0 | Z7: =Z20-(Z58+Z71) -> 0 | ... AE7: =AE20-(AE58+AE71) -> 0 | AG7: =AG20-(AG58+AG71) -> 0 | AH7: =AH20-(AH58+AH71) -> 0 | AI7: =AI20-(AI58+AI71) -> 0 | AJ7: =AJ20-(AJ58+AJ71) -> 0 | AK7: =AK20-(AK58+AK71) -> 0 | AL7: =AL20-(AL58+AL71) -> 0 | AM7: =AM20-(AM58+AM71) -> 0 | AN7: =AN20-(AN58+AN71) -> 0 | ... AS7: =AS20-(AS58+AS71) -> 0 | AU7: =AU20-(AU58+AU71) -> 0 | AV7: =AV20-(AV58+AV71) -> 0 | AW7: =AW20-(AW58+AW71) -> 0 | AX7: =AX20-(AX58+AX71) -> 0 | AY7: =AY20-(AY58+AY71) -> 0 | AZ7: =AZ20-(AZ58+AZ71) -> 0 | BA7: =BA20-(BA58+BA71) -> 0 | BB7: =BB20-(BB58+BB71) -> 0 | ... BG7: =BG20-(BG58+BG71) -> 0 | BI7: =BI20-(BI58+BI71) -> 0 | BJ7: =BJ20-(BJ58+BJ71) -> 0 | BK7: =BK20-(BK58+BK71) -> 0 | BL7: =BL20-(BL58+BL71) -> 0 | BM7: =BM20-(BM58+BM71) -> 0 | BN7: =BN20-(BN58+BN71) -> 0 | BO7: =BO20-(BO58+BO71) -> 0 | BP7: =BP20-(BP58+BP71) -> 0 | ... BU7: =BU20-(BU58+BU71) -> 0 | BW7: =BW20-(BW58+BW71) -> 0 | BX7: =BX20-(BX58+BX71) -> 0 | BY7: =BY20-(BY58+BY71) -> 0 | BZ7: =BZ20-(BZ58+BZ71) -> 0 | CA7: =CA20-(CA58+CA71) -> 0 | CB7: =CB20-(CB58+CB71) -> 0 | CC7: =CC20-(CC58+CC71) -> 0 | CD7: =CD20-(CD58+CD71) -> 0 | ... CI7: =CI20-(CI58+CI71) -> 0 | CK7: =CK20-(CK58+CK71) -> 0 | CL7: =CL20-(CL58+CL71) -> 0 | CM7: =CM20-(CM58+CM71) -> 0 | CN7: =CN20-(CN58+CN71) -> 0 | CO7: =CO20-(CO58+CO71) -> 0 | CP7: =CP20-(CP58+CP71) -> 0 | CQ7: =CQ20-(CQ58+CQ71) -> 0 | CR7: =CR20-(CR58+CR71) -> 0 | ... CW7: =CW20-(CW58+CW71) -> 0 | CY7: =CY20-(CY58+CY71) -> 0 | CZ7: =CZ20-(CZ58+CZ71) -> 0 | DA7: =DA20-(DA58+DA71) -> 0 | DB7: =DB20-(DB58+DB71) -> 0 | DC7: =DC20-(DC58+DC71) -> 0 | DD7: =DD20-(DD58+DD71) -> 0 | DE7: =DE20-(DE58+DE71) -> 0 | DF7: =DF20-(DF58+DF71) -> 0 | ... DK7: =DK20-(DK58+DK71) -> 0 | DM7: =DM20-(DM58+DM71) -> 0 | DN7: =DN20-(DN58+DN71) -> 0 | DO7: =DO20-(DO58+DO71) -> 0 | DP7: =DP20-(DP58+DP71) -> 0 | DQ7: =DQ20-(DQ58+DQ71) -> 0 | DR7: =DR20-(DR58+DR71) -> 0 | DS7: =DS20-(DS58+DS71) -> 0 | DT7: =DT20-(DT58+DT71) -> 0 | ... DY7: =DY20-(DY58+DY71) -> 0 | EA7: =EA20-(EA58+EA71) -> 0 | EB7: =EB20-(EB58+EB71) -> 0 | EC7: =EC20-(EC58+EC71) -> 0 | ED7: =ED20-(ED58+ED71) -> 0 | EE7: =EE20-(EE58+EE71) -> 0 | EF7: =EF20-(EF58+EF71) -> 0 | EG7: =EG20-(EG58+EG71) -> 0 | EH7: =EH20-(EH58+EH71) -> 0 | ... EM7: =EM20-(EM58+EM71) -> 0
C9: Income | E9: =DATE(E$5,1,1) -> 44562 | F9: =DATE(E$5,2,1) -> 44593 | G9: =DATE(E$5,3,1) -> 44621 | H9: =DATE(E$5,4,1) -> 44652 | I9: =DATE(E$5,5,1) -> 44682 | J9: =DATE(E$5,6,1) -> 44713 | K9: =DATE(E$5,7,1) -> 44743 | L9: =DATE(E$5,8,1) -> 44774 | M9: =DATE(E$5,9,1) -> 44805 | N9: =DATE(E$5,10,1) -> 44835 | O9: =DATE(E$5,11,1) -> 44866 | P9: =DATE(E$5,12,1) -> 44896 | Q9: =E$5 -> 2022 | S9: =DATE(S$5,1,1) -> 44927 | T9: =DATE(S$5,2,1) -> 44958 | U9: =DATE(S$5,3,1) -> 44986 | V9: =DATE(S$5,4,1) -> 45017 | W9: =DATE(S$5,5,1) -> 45047 | X9: =DATE(S$5,6,1) -> 45078 | Y9: =DATE(S$5,7,1) -> 45108 | Z9: =DATE(S$5,8,1) -> 45139 | AA9: =DATE(S$5,9,1) -> 45170 | AB9: =DATE(S$5,10,1) -> 45200 | AC9: =DATE(S$5,11,1) -> 45231 | AD9: =DATE(S$5,12,1) -> 45261 | AE9: =S$5 -> 2023 | AG9: =DATE(AG$5,1,1) -> 45292 | AH9: =DATE(AG$5,2,1) -> 45323 | AI9: =DATE(AG$5,3,1) -> 45352 | AJ9: =DATE(AG$5,4,1) -> 45383 | AK9: =DATE(AG$5,5,1) -> 45413 | AL9: =DATE(AG$5,6,1) -> 45444 | AM9: =DATE(AG$5,7,1) -> 45474 | AN9: =DATE(AG$5,8,1) -> 45505 | AO9: =DATE(AG$5,9,1) -> 45536 | AP9: =DATE(AG$5,10,1) -> 45566 | AQ9: =DATE(AG$5,11,1) -> 45597 | AR9: =DATE(AG$5,12,1) -> 45627 | AS9: =AG$5 -> 2024 | AU9: =DATE(AU$5,1,1) -> 45658 | AV9: =DATE(AU$5,2,1) -> 45689 | AW9: =DATE(AU$5,3,1) -> 45717 | AX9: =DATE(AU$5,4,1) -> 45748 | AY9: =DATE(AU$5,5,1) -> 45778 | AZ9: =DATE(AU$5,6,1) -> 45809 | BA9: =DATE(AU$5,7,1) -> 45839 | BB9: =DATE(AU$5,8,1) -> 45870 | BC9: =DATE(AU$5,9,1) -> 45901 | BD9: =DATE(AU$5,10,1) -> 45931 | BE9: =DATE(AU$5,11,1) -> 45962 | BF9: =DATE(AU$5,12,1) -> 45992 | BG9: =AU$5 -> 2025 | BI9: =DATE(BI$5,1,1) -> 46023 | BJ9: =DATE(BI$5,2,1) -> 46054 | BK9: =DATE(BI$5,3,1) -> 46082 | BL9: =DATE(BI$5,4,1) -> 46113 | BM9: =DATE(BI$5,5,1) -> 46143 | BN9: =DATE(BI$5,6,1) -> 46174 | BO9: =DATE(BI$5,7,1) -> 46204 | BP9: =DATE(BI$5,8,1) -> 46235 | BQ9: =DATE(BI$5,9,1) -> 46266 | BR9: =DATE(BI$5,10,1) -> 46296 | BS9: =DATE(BI$5,11,1) -> 46327 | BT9: =DATE(BI$5,12,1) -> 46357 | BU9: =BI$5 -> 2026 | BW9: =DATE(BW$5,1,1) -> 46388 | BX9: =DATE(BW$5,2,1) -> 46419 | BY9: =DATE(BW$5,3,1) -> 46447 | BZ9: =DATE(BW$5,4,1) -> 46478 | CA9: =DATE(BW$5,5,1) -> 46508 | CB9: =DATE(BW$5,6,1) -> 46539 | CC9: =DATE(BW$5,7,1) -> 46569 | CD9: =DATE(BW$5,8,1) -> 46600 | CE9: =DATE(BW$5,9,1) -> 46631 | CF9: =DATE(BW$5,10,1) -> 46661 | CG9: =DATE(BW$5,11,1) -> 46692 | CH9: =DATE(BW$5,12,1) -> 46722 | CI9: =BW$5 -> 2027 | CK9: =DATE(CK$5,1,1) -> 46753 | CL9: =DATE(CK$5,2,1) -> 46784 | CM9: =DATE(CK$5,3,1) -> 46813 | CN9: =DATE(CK$5,4,1) -> 46844 | CO9: =DATE(CK$5,5,1) -> 46874 | CP9: =DATE(CK$5,6,1) -> 46905 | CQ9: =DATE(CK$5,7,1) -> 46935 | CR9: =DATE(CK$5,8,1) -> 46966 | CS9: =DATE(CK$5,9,1) -> 46997 | CT9: =DATE(CK$5,10,1) -> 47027 | CU9: =DATE(CK$5,11,1) -> 47058 | CV9: =DATE(CK$5,12,1) -> 47088 | CW9: =CK$5 -> 2028 | CY9: =DATE(CY$5,1,1) -> 47119 | CZ9: =DATE(CY$5,2,1) -> 47150 | DA9: =DATE(CY$5,3,1) -> 47178 | DB9: =DATE(CY$5,4,1) -> 47209 | DC9: =DATE(CY$5,5,1) -> 47239 | DD9: =DATE(CY$5,6,1) -> 47270 | DE9: =DATE(CY$5,7,1) -> 47300 | DF9: =DATE(CY$5,8,1) -> 47331 | DG9: =DATE(CY$5,9,1) -> 47362 | DH9: =DATE(CY$5,10,1) -> 47392 | DI9: =DATE(CY$5,11,1) -> 47423 | DJ9: =DATE(CY$5,12,1) -> 47453 | DK9: =CY$5 -> 2029 | DM9: =DATE(DM$5,1,1) -> 47484 | DN9: =DATE(DM$5,2,1) -> 47515 | DO9: =DATE(DM$5,3,1) -> 47543 | DP9: =DATE(DM$5,4,1) -> 47574 | DQ9: =DATE(DM$5,5,1) -> 47604 | DR9: =DATE(DM$5,6,1) -> 47635 | DS9: =DATE(DM$5,7,1) -> 47665 | DT9: =DATE(DM$5,8,1) -> 47696 | DU9: =DATE(DM$5,9,1) -> 47727 | DV9: =DATE(DM$5,10,1) -> 47757 | DW9: =DATE(DM$5,11,1) -> 47788 | DX9: =DATE(DM$5,12,1) -> 47818 | DY9: =DM$5 -> 2030 | EA9: =DATE(EA$5,1,1) -> 47849 | EB9: =DATE(EA$5,2,1) -> 47880 | EC9: =DATE(EA$5,3,1) -> 47908 | ED9: =DATE(EA$5,4,1) -> 47939 | EE9: =DATE(EA$5,5,1) -> 47969 | EF9: =DATE(EA$5,6,1) -> 48000 | EG9: =DATE(EA$5,7,1) -> 48030 | EH9: =DATE(EA$5,8,1) -> 48061 | EI9: =DATE(EA$5,9,1) -> 48092 | EJ9: =DATE(EA$5,10,1) -> 48122 | EK9: =DATE(EA$5,11,1) -> 48153 | EL9: =DATE(EA$5,12,1) -> 48183 | EM9: =EA$5 -> 2031
C10: Enter Income Category… | Q10: =SUM(E10:P10) -> 0 | AE10: =SUM(S10:AD10) -> 0 | AS10: =SUM(AG10:AR10) -> 0 | BG10: =SUM(AU10:BF10) -> 0 | BU10: =SUM(BI10:BT10) -> 0 | CI10: =SUM(BW10:CH10) -> 0 | CW10: =SUM(CK10:CV10) -> 0 | DK10: =SUM(CY10:DJ10) -> 0 | DY10: =SUM(DM10:DX10) -> 0 | EM10: =SUM(EA10:EL10) -> 0
C11: Enter Income Category… | Q11: =SUM(E11:P11) -> 0 | AE11: =SUM(S11:AD11) -> 0 | AS11: =SUM(AG11:AR11) -> 0 | BG11: =SUM(AU11:BF11) -> 0 | BU11: =SUM(BI11:BT11) -> 0 | CI11: =SUM(BW11:CH11) -> 0 | CW11: =SUM(CK11:CV11) -> 0 | DK11: =SUM(CY11:DJ11) -> 0 | DY11: =SUM(DM11:DX11) -> 0 | EM11: =SUM(EA11:EL11) -> 0
C12: Enter Income Category… | Q12: =SUM(E12:P12) -> 0 | AE12: =SUM(S12:AD12) -> 0 | AS12: =SUM(AG12:AR12) -> 0 | BG12: =SUM(AU12:BF12) -> 0 | BU12: =SUM(BI12:BT12) -> 0 | CI12: =SUM(BW12:CH12) -> 0 | CW12: =SUM(CK12:CV12) -> 0 | DK12: =SUM(CY12:DJ12) -> 0 | DY12: =SUM(DM12:DX12) -> 0 | EM12: =SUM(EA12:EL12) -> 0
C13: Enter Income Category… | Q13: =SUM(E13:P13) -> 0 | AE13: =SUM(S13:AD13) -> 0 | AS13: =SUM(AG13:AR13) -> 0 | BG13: =SUM(AU13:BF13) -> 0 | BU13: =SUM(BI13:BT13) -> 0 | CI13: =SUM(BW13:CH13) -> 0 | CW13: =SUM(CK13:CV13) -> 0 | DK13: =SUM(CY13:DJ13) -> 0 | DY13: =SUM(DM13:DX13) -> 0 | EM13: =SUM(EA13:EL13) -> 0
C14: Enter Income Category… | Q14: =SUM(E14:P14) -> 0 | AE14: =SUM(S14:AD14) -> 0 | AS14: =SUM(AG14:AR14) -> 0 | BG14: =SUM(AU14:BF14) -> 0 | BU14: =SUM(BI14:BT14) -> 0 | CI14: =SUM(BW14:CH14) -> 0 | CW14: =SUM(CK14:CV14) -> 0 | DK14: =SUM(CY14:DJ14) -> 0 | DY14: =SUM(DM14:DX14) -> 0 | EM14: =SUM(EA14:EL14) -> 0
C15: Enter Income Category… | Q15: =SUM(E15:P15) -> 0 | AE15: =SUM(S15:AD15) -> 0 | AS15: =SUM(AG15:AR15) -> 0 | BG15: =SUM(AU15:BF15) -> 0 | BU15: =SUM(BI15:BT15) -> 0 | CI15: =SUM(BW15:CH15) -> 0 | CW15: =SUM(CK15:CV15) -> 0 | DK15: =SUM(CY15:DJ15) -> 0 | DY15: =SUM(DM15:DX15) -> 0 | EM15: =SUM(EA15:EL15) -> 0
C16: Enter Income Category… | Q16: =SUM(E16:P16) -> 0 | AE16: =SUM(S16:AD16) -> 0 | AS16: =SUM(AG16:AR16) -> 0 | BG16: =SUM(AU16:BF16) -> 0 | BU16: =SUM(BI16:BT16) -> 0 | CI16: =SUM(BW16:CH16) -> 0 | CW16: =SUM(CK16:CV16) -> 0 | DK16: =SUM(CY16:DJ16) -> 0 | DY16: =SUM(DM16:DX16) -> 0 | EM16: =SUM(EA16:EL16) -> 0
C17: Enter Income Category… | Q17: =SUM(E17:P17) -> 0 | AE17: =SUM(S17:AD17) -> 0 | AS17: =SUM(AG17:AR17) -> 0 | BG17: =SUM(AU17:BF17) -> 0 | BU17: =SUM(BI17:BT17) -> 0 | CI17: =SUM(BW17:CH17) -> 0 | CW17: =SUM(CK17:CV17) -> 0 | DK17: =SUM(CY17:DJ17) -> 0 | DY17: =SUM(DM17:DX17) -> 0 | EM17: =SUM(EA17:EL17) -> 0
C18: Enter Income Category… | Q18: =SUM(E18:P18) -> 0 | AE18: =SUM(S18:AD18) -> 0 | AS18: =SUM(AG18:AR18) -> 0 | BG18: =SUM(AU18:BF18) -> 0 | BU18: =SUM(BI18:BT18) -> 0 | CI18: =SUM(BW18:CH18) -> 0 | CW18: =SUM(CK18:CV18) -> 0 | DK18: =SUM(CY18:DJ18) -> 0 | DY18: =SUM(DM18:DX18) -> 0 | EM18: =SUM(EA18:EL18) -> 0
C19: Enter Income Category… | Q19: =SUM(E19:P19) -> 0 | AE19: =SUM(S19:AD19) -> 0 | AS19: =SUM(AG19:AR19) -> 0 | BG19: =SUM(AU19:BF19) -> 0 | BU19: =SUM(BI19:BT19) -> 0 | CI19: =SUM(BW19:CH19) -> 0 | CW19: =SUM(CK19:CV19) -> 0 | DK19: =SUM(CY19:DJ19) -> 0 | DY19: =SUM(DM19:DX19) -> 0 | EM19: =SUM(EA19:EL19) -> 0
C20: Total | E20: {=SUM(INDIRECT(ADDRESS(income_min_row, COLUMN()) & ":" & ADDRESS(income_max_row, COLUMN())))} -> 0 | F20: {=SUM(INDIRECT(ADDRESS(income_min_row, COLUMN()) & ":" & ADDRESS(income_max_row, COLUMN())))} -> 0 | G20: {=SUM(INDIRECT(ADDRESS(income_min_row, COLUMN()) & ":" & ADDRESS(income_max_row, COLUMN())))} -> 0 | H20: {=SUM(INDIRECT(ADDRESS(income_min_row, COLUMN()) & ":" & ADDRESS(income_max_row, COLUMN())))} -> 0 | I20: {=SUM(INDIRECT(ADDRESS(income_min_row, COLUMN()) & ":" & ADDRESS(income_max_row, COLUMN())))} -> 0 | J20: {=SUM(INDIRECT(ADDRESS(income_min_row, COLUMN()) & ":" & ADDRESS(income_max_row, COLUMN())))} -> 0 | K20: {=SUM(INDIRECT(ADDRESS(income_min_row, COLUMN()) & ":" & ADDRESS(income_max_row, COLUMN())))} -> 0 | L20: {=SUM(INDIRECT(ADDRESS(income_min_row, COLUMN()) & ":" & ADDRESS(income_max_row, COLUMN())))} -> 0 | ... Q20: {=SUM(INDIRECT(ADDRESS(income_min_row, COLUMN()) & ":" & ADDRESS(income_max_row, COLUMN())))} -> 0 | S20: {=SUM(INDIRECT(ADDRESS(income_min_row, COLUMN()) & ":" & ADDRESS(income_max_row, COLUMN())))} -> 0 | T20: {=SUM(INDIRECT(ADDRESS(income_min_row, COLUMN()) & ":" & ADDRESS(income_max_row, COLUMN())))} -> 0 | U20: {=SUM(INDIRECT(ADDRESS(income_min_row, COLUMN()) & ":" & ADDRESS(income_max_row, COLUMN())))} -> 0 | V20: {=SUM(INDIRECT(ADDRESS(income_min_row, COLUMN()) & ":" & ADDRESS(income_max_row, COLUMN())))} -> 0 | W20: {=SUM(INDIRECT(ADDRESS(income_min_row, COLUMN()) & ":" & ADDRESS(income_max_row, COLUMN())))} -> 0 | X20: {=SUM(INDIRECT(ADDRESS(income_min_row, COLUMN()) & ":" & ADDRESS(income_max_row, COLUMN())))} -> 0 | Y20: {=SUM(INDIRECT(ADDRESS(income_min_row, COLUMN()) & ":" & ADDRESS(income_max_row, COLUMN())))} -> 0 | Z20: {=SUM(INDIRECT(ADDRESS(income_min_row, COLUMN()) & ":" & ADDRESS(income_max_row, COLUMN())))} -> 0 | ... AE20: {=SUM(INDIRECT(ADDRESS(income_min_row, COLUMN()) & ":" & ADDRESS(income_max_row, COLUMN())))} -> 0 | AG20: {=SUM(INDIRECT(ADDRESS(income_min_row, COLUMN()) & ":" & ADDRESS(income_max_row, COLUMN())))} -> 0 | AH20: {=SUM(INDIRECT(ADDRESS(income_min_row, COLUMN()) & ":" & ADDRESS(income_max_row, COLUMN())))} -> 0 | AI20: {=SUM(INDIRECT(ADDRESS(income_min_row, COLUMN()) & ":" & ADDRESS(income_max_row, COLUMN())))} -> 0 | AJ20: {=SUM(INDIRECT(ADDRESS(income_min_row, COLUMN()) & ":" & ADDRESS(income_max_row, COLUMN())))} -> 0 | AK20: {=SUM(INDIRECT(ADDRESS(income_min_row, COLUMN()) & ":" & ADDRESS(income_max_row, COLUMN())))} -> 0 | AL20: {=SUM(INDIRECT(ADDRESS(income_min_row, COLUMN()) & ":" & ADDRESS(income_max_row, COLUMN())))} -> 0 | AM20: {=SUM(INDIRECT(ADDRESS(income_min_row, COLUMN()) & ":" & ADDRESS(income_max_row, COLUMN())))} -> 0 | AN20: {=SUM(INDIRECT(ADDRESS(income_min_row, COLUMN()) & ":" & ADDRESS(income_max_row, COLUMN())))} -> 0 | ... AS20: {=SUM(INDIRECT(ADDRESS(income_min_row, COLUMN()) & ":" & ADDRESS(income_max_row, COLUMN())))} -> 0 | AU20: {=SUM(INDIRECT(ADDRESS(income_min_row, COLUMN()) & ":" & ADDRESS(income_max_row, COLUMN())))} -> 0 | AV20: {=SUM(INDIRECT(ADDRESS(income_min_row, COLUMN()) & ":" & ADDRESS(income_max_row, COLUMN())))} -> 0 | AW20: {=SUM(INDIRECT(ADDRESS(income_min_row, COLUMN()) & ":" & ADDRESS(income_max_row, COLUMN())))} -> 0 | AX20: {=SUM(INDIRECT(ADDRESS(income_min_row, COLUMN()) & ":" & ADDRESS(income_max_row, COLUMN())))} -> 0 | AY20: {=SUM(INDIRECT(ADDRESS(income_min_row, COLUMN()) & ":" & ADDRESS(income_max_row, COLUMN())))} -> 0 | AZ20: {=SUM(INDIRECT(ADDRESS(income_min_row, COLUMN()) & ":" & ADDRESS(income_max_row, COLUMN())))} -> 0 | BA20: {=SUM(INDIRECT(ADDRESS(income_min_row, COLUMN()) & ":" & ADDRESS(income_max_row, COLUMN())))} -> 0 | BB20: {=SUM(INDIRECT(ADDRESS(income_min_row, COLUMN()) & ":" & ADDRESS(income_max_row, COLUMN())))} -> 0 | ... BG20: {=SUM(INDIRECT(ADDRESS(income_min_row, COLUMN()) & ":" & ADDRESS(income_max_row, COLUMN())))} -> 0 | BI20: {=SUM(INDIRECT(ADDRESS(income_min_row, COLUMN()) & ":" & ADDRESS(income_max_row, COLUMN())))} -> 0 | BJ20: {=SUM(INDIRECT(ADDRESS(income_min_row, COLUMN()) & ":" & ADDRESS(income_max_row, COLUMN())))} -> 0 | BK20: {=SUM(INDIRECT(ADDRESS(income_min_row, COLUMN()) & ":" & ADDRESS(income_max_row, COLUMN())))} -> 0 | BL20: {=SUM(INDIRECT(ADDRESS(income_min_row, COLUMN()) & ":" & ADDRESS(income_max_row, COLUMN())))} -> 0 | BM20: {=SUM(INDIRECT(ADDRESS(income_min_row, COLUMN()) & ":" & ADDRESS(income_max_row, COLUMN())))} -> 0 | BN20: {=SUM(INDIRECT(ADDRESS(income_min_row, COLUMN()) & ":" & ADDRESS(income_max_row, COLUMN())))} -> 0 | BO20: {=SUM(INDIRECT(ADDRESS(income_min_row, COLUMN()) & ":" & ADDRESS(income_max_row, COLUMN())))} -> 0 | BP20: {=SUM(INDIRECT(ADDRESS(income_min_row, COLUMN()) & ":" & ADDRESS(income_max_row, COLUMN())))} -> 0 | ... BU20: {=SUM(INDIRECT(ADDRESS(income_min_row, COLUMN()) & ":" & ADDRESS(income_max_row, COLUMN())))} -> 0 | BW20: {=SUM(INDIRECT(ADDRESS(income_min_row, COLUMN()) & ":" & ADDRESS(income_max_row, COLUMN())))} -> 0 | BX20: {=SUM(INDIRECT(ADDRESS(income_min_row, COLUMN()) & ":" & ADDRESS(income_max_row, COLUMN())))} -> 0 | BY20: {=SUM(INDIRECT(ADDRESS(income_min_row, COLUMN()) & ":" & ADDRESS(income_max_row, COLUMN())))} -> 0 | BZ20: {=SUM(INDIRECT(ADDRESS(income_min_row, COLUMN()) & ":" & ADDRESS(income_max_row, COLUMN())))} -> 0 | CA20: {=SUM(INDIRECT(ADDRESS(income_min_row, COLUMN()) & ":" & ADDRESS(income_max_row, COLUMN())))} -> 0 | CB20: {=SUM(INDIRECT(ADDRESS(income_min_row, COLUMN()) & ":" & ADDRESS(income_max_row, COLUMN())))} -> 0 | CC20: {=SUM(INDIRECT(ADDRESS(income_min_row, COLUMN()) & ":" & ADDRESS(income_max_row, COLUMN())))} -> 0 | CD20: {=SUM(INDIRECT(ADDRESS(income_min_row, COLUMN()) & ":" & ADDRESS(income_max_row, COLUMN())))} -> 0 | ... CI20: {=SUM(INDIRECT(ADDRESS(income_min_row, COLUMN()) & ":" & ADDRESS(income_max_row, COLUMN())))} -> 0 | CK20: {=SUM(INDIRECT(ADDRESS(income_min_row, COLUMN()) & ":" & ADDRESS(income_max_row, COLUMN())))} -> 0 | CL20: {=SUM(INDIRECT(ADDRESS(income_min_row, COLUMN()) & ":" & ADDRESS(income_max_row, COLUMN())))} -> 0 | CM20: {=SUM(INDIRECT(ADDRESS(income_min_row, COLUMN()) & ":" & ADDRESS(income_max_row, COLUMN())))} -> 0 | CN20: {=SUM(INDIRECT(ADDRESS(income_min_row, COLUMN()) & ":" & ADDRESS(income_max_row, COLUMN())))} -> 0 | CO20: {=SUM(INDIRECT(ADDRESS(income_min_row, COLUMN()) & ":" & ADDRESS(income_max_row, COLUMN())))} -> 0 | CP20: {=SUM(INDIRECT(ADDRESS(income_min_row, COLUMN()) & ":" & ADDRESS(income_max_row, COLUMN())))} -> 0 | CQ20: {=SUM(INDIRECT(ADDRESS(income_min_row, COLUMN()) & ":" & ADDRESS(income_max_row, COLUMN())))} -> 0 | CR20: {=SUM(INDIRECT(ADDRESS(income_min_row, COLUMN()) & ":" & ADDRESS(income_max_row, COLUMN())))} -> 0 | ... CW20: {=SUM(INDIRECT(ADDRESS(income_min_row, COLUMN()) & ":" & ADDRESS(income_max_row, COLUMN())))} -> 0 | CY20: {=SUM(INDIRECT(ADDRESS(income_min_row, COLUMN()) & ":" & ADDRESS(income_max_row, COLUMN())))} -> 0 | CZ20: {=SUM(INDIRECT(ADDRESS(income_min_row, COLUMN()) & ":" & ADDRESS(income_max_row, COLUMN())))} -> 0 | DA20: {=SUM(INDIRECT(ADDRESS(income_min_row, COLUMN()) & ":" & ADDRESS(income_max_row, COLUMN())))} -> 0 | DB20: {=SUM(INDIRECT(ADDRESS(income_min_row, COLUMN()) & ":" & ADDRESS(income_max_row, COLUMN())))} -> 0 | DC20: {=SUM(INDIRECT(ADDRESS(income_min_row, COLUMN()) & ":" & ADDRESS(income_max_row, COLUMN())))} -> 0 | DD20: {=SUM(INDIRECT(ADDRESS(income_min_row, COLUMN()) & ":" & ADDRESS(income_max_row, COLUMN())))} -> 0 | DE20: {=SUM(INDIRECT(ADDRESS(income_min_row, COLUMN()) & ":" & ADDRESS(income_max_row, COLUMN())))} -> 0 | DF20: {=SUM(INDIRECT(ADDRESS(income_min_row, COLUMN()) & ":" & ADDRESS(income_max_row, COLUMN())))} -> 0 | ... DK20: {=SUM(INDIRECT(ADDRESS(income_min_row, COLUMN()) & ":" & ADDRESS(income_max_row, COLUMN())))} -> 0 | DM20: {=SUM(INDIRECT(ADDRESS(income_min_row, COLUMN()) & ":" & ADDRESS(income_max_row, COLUMN())))} -> 0 | DN20: {=SUM(INDIRECT(ADDRESS(income_min_row, COLUMN()) & ":" & ADDRESS(income_max_row, COLUMN())))} -> 0 | DO20: {=SUM(INDIRECT(ADDRESS(income_min_row, COLUMN()) & ":" & ADDRESS(income_max_row, COLUMN())))} -> 0 | DP20: {=SUM(INDIRECT(ADDRESS(income_min_row, COLUMN()) & ":" & ADDRESS(income_max_row, COLUMN())))} -> 0 | DQ20: {=SUM(INDIRECT(ADDRESS(income_min_row, COLUMN()) & ":" & ADDRESS(income_max_row, COLUMN())))} -> 0 | DR20: {=SUM(INDIRECT(ADDRESS(income_min_row, COLUMN()) & ":" & ADDRESS(income_max_row, COLUMN())))} -> 0 | DS20: {=SUM(INDIRECT(ADDRESS(income_min_row, COLUMN()) & ":" & ADDRESS(income_max_row, COLUMN())))} -> 0 | DT20: {=SUM(INDIRECT(ADDRESS(income_min_row, COLUMN()) & ":" & ADDRESS(income_max_row, COLUMN())))} -> 0 | ... DY20: {=SUM(INDIRECT(ADDRESS(income_min_row, COLUMN()) & ":" & ADDRESS(income_max_row, COLUMN())))} -> 0 | EA20: {=SUM(INDIRECT(ADDRESS(income_min_row, COLUMN()) & ":" & ADDRESS(income_max_row, COLUMN())))} -> 0 | EB20: {=SUM(INDIRECT(ADDRESS(income_min_row, COLUMN()) & ":" & ADDRESS(income_max_row, COLUMN())))} -> 0 | EC20: {=SUM(INDIRECT(ADDRESS(income_min_row, COLUMN()) & ":" & ADDRESS(income_max_row, COLUMN())))} -> 0 | ED20: {=SUM(INDIRECT(ADDRESS(income_min_row, COLUMN()) & ":" & ADDRESS(income_max_row, COLUMN())))} -> 0 | EE20: {=SUM(INDIRECT(ADDRESS(income_min_row, COLUMN()) & ":" & ADDRESS(income_max_row, COLUMN())))} -> 0 | EF20: {=SUM(INDIRECT(ADDRESS(income_min_row, COLUMN()) & ":" & ADDRESS(income_max_row, COLUMN())))} -> 0 | EG20: {=SUM(INDIRECT(ADDRESS(income_min_row, COLUMN()) & ":" & ADDRESS(income_max_row, COLUMN())))} -> 0 | EH20: {=SUM(INDIRECT(ADDRESS(income_min_row, COLUMN()) & ":" & ADDRESS(income_max_row, COLUMN())))} -> 0 | ... EM20: {=SUM(INDIRECT(ADDRESS(income_min_row, COLUMN()) & ":" & ADDRESS(income_max_row, COLUMN())))} -> 0
C22: Expenses | E22: =DATE(E$5,1,1) -> 44562 | F22: =DATE(E$5,2,1) -> 44593 | G22: =DATE(E$5,3,1) -> 44621 | H22: =DATE(E$5,4,1) -> 44652 | I22: =DATE(E$5,5,1) -> 44682 | J22: =DATE(E$5,6,1) -> 44713 | K22: =DATE(E$5,7,1) -> 44743 | L22: =DATE(E$5,8,1) -> 44774 | M22: =DATE(E$5,9,1) -> 44805 | N22: =DATE(E$5,10,1) -> 44835 | O22: =DATE(E$5,11,1) -> 44866 | P22: =DATE(E$5,12,1) -> 44896 | Q22: =E$5 -> 2022 | S22: =DATE(S$5,1,1) -> 44927 | T22: =DATE(S$5,2,1) -> 44958 | U22: =DATE(S$5,3,1) -> 44986 | V22: =DATE(S$5,4,1) -> 45017 | W22: =DATE(S$5,5,1) -> 45047 | X22: =DATE(S$5,6,1) -> 45078 | Y22: =DATE(S$5,7,1) -> 45108 | Z22: =DATE(S$5,8,1) -> 45139 | AA22: =DATE(S$5,9,1) -> 45170 | AB22: =DATE(S$5,10,1) -> 45200 | AC22: =DATE(S$5,11,1) -> 45231 | AD22: =DATE(S$5,12,1) -> 45261 | AE22: =S$5 -> 2023 | AG22: =DATE(AG$5,1,1) -> 45292 | AH22: =DATE(AG$5,2,1) -> 45323 | AI22: =DATE(AG$5,3,1) -> 45352 | AJ22: =DATE(AG$5,4,1) -> 45383 | AK22: =DATE(AG$5,5,1) -> 45413 | AL22: =DATE(AG$5,6,1) -> 45444 | AM22: =DATE(AG$5,7,1) -> 45474 | AN22: =DATE(AG$5,8,1) -> 45505 | AO22: =DATE(AG$5,9,1) -> 45536 | AP22: =DATE(AG$5,10,1) -> 45566 | AQ22: =DATE(AG$5,11,1) -> 45597 | AR22: =DATE(AG$5,12,1) -> 45627 | AS22: =AG$5 -> 2024 | AU22: =DATE(AU$5,1,1) -> 45658 | AV22: =DATE(AU$5,2,1) -> 45689 | AW22: =DATE(AU$5,3,1) -> 45717 | AX22: =DATE(AU$5,4,1) -> 45748 | AY22: =DATE(AU$5,5,1) -> 45778 | AZ22: =DATE(AU$5,6,1) -> 45809 | BA22: =DATE(AU$5,7,1) -> 45839 | BB22: =DATE(AU$5,8,1) -> 45870 | BC22: =DATE(AU$5,9,1) -> 45901 | BD22: =DATE(AU$5,10,1) -> 45931 | BE22: =DATE(AU$5,11,1) -> 45962 | BF22: =DATE(AU$5,12,1) -> 45992 | BG22: =AU$5 -> 2025 | BI22: =DATE(BI$5,1,1) -> 46023 | BJ22: =DATE(BI$5,2,1) -> 46054 | BK22: =DATE(BI$5,3,1) -> 46082 | BL22: =DATE(BI$5,4,1) -> 46113 | BM22: =DATE(BI$5,5,1) -> 46143 | BN22: =DATE(BI$5,6,1) -> 46174 | BO22: =DATE(BI$5,7,1) -> 46204 | BP22: =DATE(BI$5,8,1) -> 46235 | BQ22: =DATE(BI$5,9,1) -> 46266 | BR22: =DATE(BI$5,10,1) -> 46296 | BS22: =DATE(BI$5,11,1) -> 46327 | BT22: =DATE(BI$5,12,1) -> 46357 | BU22: =BI$5 -> 2026 | BW22: =DATE(BW$5,1,1) -> 46388 | BX22: =DATE(BW$5,2,1) -> 46419 | BY22: =DATE(BW$5,3,1) -> 46447 | BZ22: =DATE(BW$5,4,1) -> 46478 | CA22: =DATE(BW$5,5,1) -> 46508 | CB22: =DATE(BW$5,6,1) -> 46539 | CC22: =DATE(BW$5,7,1) -> 46569 | CD22: =DATE(BW$5,8,1) -> 46600 | CE22: =DATE(BW$5,9,1) -> 46631 | CF22: =DATE(BW$5,10,1) -> 46661 | CG22: =DATE(BW$5,11,1) -> 46692 | CH22: =DATE(BW$5,12,1) -> 46722 | CI22: =BW$5 -> 2027 | CK22: =DATE(CK$5,1,1) -> 46753 | CL22: =DATE(CK$5,2,1) -> 46784 | CM22: =DATE(CK$5,3,1) -> 46813 | CN22: =DATE(CK$5,4,1) -> 46844 | CO22: =DATE(CK$5,5,1) -> 46874 | CP22: =DATE(CK$5,6,1) -> 46905 | CQ22: =DATE(CK$5,7,1) -> 46935 | CR22: =DATE(CK$5,8,1) -> 46966 | CS22: =DATE(CK$5,9,1) -> 46997 | CT22: =DATE(CK$5,10,1) -> 47027 | CU22: =DATE(CK$5,11,1) -> 47058 | CV22: =DATE(CK$5,12,1) -> 47088 | CW22: =CK$5 -> 2028 | CY22: =DATE(CY$5,1,1) -> 47119 | CZ22: =DATE(CY$5,2,1) -> 47150 | DA22: =DATE(CY$5,3,1) -> 47178 | DB22: =DATE(CY$5,4,1) -> 47209 | DC22: =DATE(CY$5,5,1) -> 47239 | DD22: =DATE(CY$5,6,1) -> 47270 | DE22: =DATE(CY$5,7,1) -> 47300 | DF22: =DATE(CY$5,8,1) -> 47331 | DG22: =DATE(CY$5,9,1) -> 47362 | DH22: =DATE(CY$5,10,1) -> 47392 | DI22: =DATE(CY$5,11,1) -> 47423 | DJ22: =DATE(CY$5,12,1) -> 47453 | DK22: =CY$5 -> 2029 | DM22: =DATE(DM$5,1,1) -> 47484 | DN22: =DATE(DM$5,2,1) -> 47515 | DO22: =DATE(DM$5,3,1) -> 47543 | DP22: =DATE(DM$5,4,1) -> 47574 | DQ22: =DATE(DM$5,5,1) -> 47604 | DR22: =DATE(DM$5,6,1) -> 47635 | DS22: =DATE(DM$5,7,1) -> 47665 | DT22: =DATE(DM$5,8,1) -> 47696 | DU22: =DATE(DM$5,9,1) -> 47727 | DV22: =DATE(DM$5,10,1) -> 47757 | DW22: =DATE(DM$5,11,1) -> 47788 | DX22: =DATE(DM$5,12,1) -> 47818 | DY22: =DM$5 -> 2030 | EA22: =DATE(EA$5,1,1) -> 47849 | EB22: =DATE(EA$5,2,1) -> 47880 | EC22: =DATE(EA$5,3,1) -> 47908 | ED22: =DATE(EA$5,4,1) -> 47939 | EE22: =DATE(EA$5,5,1) -> 47969 | EF22: =DATE(EA$5,6,1) -> 48000 | EG22: =DATE(EA$5,7,1) -> 48030 | EH22: =DATE(EA$5,8,1) -> 48061 | EI22: =DATE(EA$5,9,1) -> 48092 | EJ22: =DATE(EA$5,10,1) -> 48122 | EK22: =DATE(EA$5,11,1) -> 48153 | EL22: =DATE(EA$5,12,1) -> 48183 | EM22: =EA$5 -> 2031
C23: Enter Expenses Category… | Q23: =SUM(E23:P23) -> 0 | AE23: =SUM(S23:AD23) -> 0 | AS23: =SUM(AG23:AR23) -> 0 | BG23: =SUM(AU23:BF23) -> 0 | BU23: =SUM(BI23:BT23) -> 0 | CI23: =SUM(BW23:CH23) -> 0 | CW23: =SUM(CK23:CV23) -> 0 | DK23: =SUM(CY23:DJ23) -> 0 | DY23: =SUM(DM23:DX23) -> 0 | EM23: =SUM(EA23:EL23) -> 0
C24: Enter Expenses Category… | Q24: =SUM(E24:P24) -> 0 | AE24: =SUM(S24:AD24) -> 0 | AS24: =SUM(AG24:AR24) -> 0 | BG24: =SUM(AU24:BF24) -> 0 | BU24: =SUM(BI24:BT24) -> 0 | CI24: =SUM(BW24:CH24) -> 0 | CW24: =SUM(CK24:CV24) -> 0 | DK24: =SUM(CY24:DJ24) -> 0 | DY24: =SUM(DM24:DX24) -> 0 | EM24: =SUM(EA24:EL24) -> 0
C25: Enter Expenses Category… | Q25: =SUM(E25:P25) -> 0 | AE25: =SUM(S25:AD25) -> 0 | AS25: =SUM(AG25:AR25) -> 0 | BG25: =SUM(AU25:BF25) -> 0 | BU25: =SUM(BI25:BT25) -> 0 | CI25: =SUM(BW25:CH25) -> 0 | CW25: =SUM(CK25:CV25) -> 0 | DK25: =SUM(CY25:DJ25) -> 0 | DY25: =SUM(DM25:DX25) -> 0 | EM25: =SUM(EA25:EL25) -> 0
C26: Enter Expenses Category… | Q26: =SUM(E26:P26) -> 0 | AE26: =SUM(S26:AD26) -> 0 | AS26: =SUM(AG26:AR26) -> 0 | BG26: =SUM(AU26:BF26) -> 0 | BU26: =SUM(BI26:BT26) -> 0 | CI26: =SUM(BW26:CH26) -> 0 | CW26: =SUM(CK26:CV26) -> 0 | DK26: =SUM(CY26:DJ26) -> 0 | DY26: =SUM(DM26:DX26) -> 0 | EM26: =SUM(EA26:EL26) -> 0
C27: Enter Expenses Category… | Q27: =SUM(E27:P27) -> 0 | AE27: =SUM(S27:AD27) -> 0 | AS27: =SUM(AG27:AR27) -> 0 | BG27: =SUM(AU27:BF27) -> 0 | BU27: =SUM(BI27:BT27) -> 0 | CI27: =SUM(BW27:CH27) -> 0 | CW27: =SUM(CK27:CV27) -> 0 | DK27: =SUM(CY27:DJ27) -> 0 | DY27: =SUM(DM27:DX27) -> 0 | EM27: =SUM(EA27:EL27) -> 0
C28: Enter Expenses Category… | Q28: =SUM(E28:P28) -> 0 | AE28: =SUM(S28:AD28) -> 0 | AS28: =SUM(AG28:AR28) -> 0 | BG28: =SUM(AU28:BF28) -> 0 | BU28: =SUM(BI28:BT28) -> 0 | CI28: =SUM(BW28:CH28) -> 0 | CW28: =SUM(CK28:CV28) -> 0 | DK28: =SUM(CY28:DJ28) -> 0 | DY28: =SUM(DM28:DX28) -> 0 | EM28: =SUM(EA28:EL28) -> 0
C29: Enter Expenses Category… | Q29: =SUM(E29:P29) -> 0 | AE29: =SUM(S29:AD29) -> 0 | AS29: =SUM(AG29:AR29) -> 0 | BG29: =SUM(AU29:BF29) -> 0 | BU29: =SUM(BI29:BT29) -> 0 | CI29: =SUM(BW29:CH29) -> 0 | CW29: =SUM(CK29:CV29) -> 0 | DK29: =SUM(CY29:DJ29) -> 0 | DY29: =SUM(DM29:DX29) -> 0 | EM29: =SUM(EA29:EL29) -> 0
C30: Enter Expenses Category… | Q30: =SUM(E30:P30) -> 0 | AE30: =SUM(S30:AD30) -> 0 | AS30: =SUM(AG30:AR30) -> 0 | BG30: =SUM(AU30:BF30) -> 0 | BU30: =SUM(BI30:BT30) -> 0 | CI30: =SUM(BW30:CH30) -> 0 | CW30: =SUM(CK30:CV30) -> 0 | DK30: =SUM(CY30:DJ30) -> 0 | DY30: =SUM(DM30:DX30) -> 0 | EM30: =SUM(EA30:EL30) -> 0
C31: Enter Expenses Category… | Q31: =SUM(E31:P31) -> 0 | AE31: =SUM(S31:AD31) -> 0 | AS31: =SUM(AG31:AR31) -> 0 | BG31: =SUM(AU31:BF31) -> 0 | BU31: =SUM(BI31:BT31) -> 0 | CI31: =SUM(BW31:CH31) -> 0 | CW31: =SUM(CK31:CV31) -> 0 | DK31: =SUM(CY31:DJ31) -> 0 | DY31: =SUM(DM31:DX31) -> 0 | EM31: =SUM(EA31:EL31) -> 0
C32: Enter Expenses Category… | Q32: =SUM(E32:P32) -> 0 | AE32: =SUM(S32:AD32) -> 0 | AS32: =SUM(AG32:AR32) -> 0 | BG32: =SUM(AU32:BF32) -> 0 | BU32: =SUM(BI32:BT32) -> 0 | CI32: =SUM(BW32:CH32) -> 0 | CW32: =SUM(CK32:CV32) -> 0 | DK32: =SUM(CY32:DJ32) -> 0 | DY32: =SUM(DM32:DX32) -> 0 | EM32: =SUM(EA32:EL32) -> 0
C33: Enter Expenses Category… | Q33: =SUM(E33:P33) -> 0 | AE33: =SUM(S33:AD33) -> 0 | AS33: =SUM(AG33:AR33) -> 0 | BG33: =SUM(AU33:BF33) -> 0 | BU33: =SUM(BI33:BT33) -> 0 | CI33: =SUM(BW33:CH33) -> 0 | CW33: =SUM(CK33:CV33) -> 0 | DK33: =SUM(CY33:DJ33) -> 0 | DY33: =SUM(DM33:DX33) -> 0 | EM33: =SUM(EA33:EL33) -> 0
C34: Enter Expenses Category… | Q34: =SUM(E34:P34) -> 0 | AE34: =SUM(S34:AD34) -> 0 | AS34: =SUM(AG34:AR34) -> 0 | BG34: =SUM(AU34:BF34) -> 0 | BU34: =SUM(BI34:BT34) -> 0 | CI34: =SUM(BW34:CH34) -> 0 | CW34: =SUM(CK34:CV34) -> 0 | DK34: =SUM(CY34:DJ34) -> 0 | DY34: =SUM(DM34:DX34) -> 0 | EM34: =SUM(EA34:EL34) -> 0
... C57: Enter Expenses Category… | Q57: =SUM(E57:P57) -> 0 | AE57: =SUM(S57:AD57) -> 0 | AS57: =SUM(AG57:AR57) -> 0 | BG57: =SUM(AU57:BF57) -> 0 | BU57: =SUM(BI57:BT57) -> 0 | CI57: =SUM(BW57:CH57) -> 0 | CW57: =SUM(CK57:CV57) -> 0 | DK57: =SUM(CY57:DJ57) -> 0 | DY57: =SUM(DM57:DX57) -> 0 | EM57: =SUM(EA57:EL57) -> 0
C58: Total | E58: {=SUM(INDIRECT(ADDRESS(expenses_min_row, COLUMN()) & ":" & ADDRESS(expenses_max_row, COLUMN())))} -> 0 | F58: {=SUM(INDIRECT(ADDRESS(expenses_min_row, COLUMN()) & ":" & ADDRESS(expenses_max_row, COLUMN())))} -> 0 | G58: {=SUM(INDIRECT(ADDRESS(expenses_min_row, COLUMN()) & ":" & ADDRESS(expenses_max_row, COLUMN())))} -> 0 | H58: {=SUM(INDIRECT(ADDRESS(expenses_min_row, COLUMN()) & ":" & ADDRESS(expenses_max_row, COLUMN())))} -> 0 | I58: {=SUM(INDIRECT(ADDRESS(expenses_min_row, COLUMN()) & ":" & ADDRESS(expenses_max_row, COLUMN())))} -> 0 | J58: {=SUM(INDIRECT(ADDRESS(expenses_min_row, COLUMN()) & ":" & ADDRESS(expenses_max_row, COLUMN())))} -> 0 | K58: {=SUM(INDIRECT(ADDRESS(expenses_min_row, COLUMN()) & ":" & ADDRESS(expenses_max_row, COLUMN())))} -> 0 | L58: {=SUM(INDIRECT(ADDRESS(expenses_min_row, COLUMN()) & ":" & ADDRESS(expenses_max_row, COLUMN())))} -> 0 | ... Q58: {=SUM(INDIRECT(ADDRESS(expenses_min_row, COLUMN()) & ":" & ADDRESS(expenses_max_row, COLUMN())))} -> 0 | S58: {=SUM(INDIRECT(ADDRESS(expenses_min_row, COLUMN()) & ":" & ADDRESS(expenses_max_row, COLUMN())))} -> 0 | T58: {=SUM(INDIRECT(ADDRESS(expenses_min_row, COLUMN()) & ":" & ADDRESS(expenses_max_row, COLUMN())))} -> 0 | U58: {=SUM(INDIRECT(ADDRESS(expenses_min_row, COLUMN()) & ":" & ADDRESS(expenses_max_row, COLUMN())))} -> 0 | V58: {=SUM(INDIRECT(ADDRESS(expenses_min_row, COLUMN()) & ":" & ADDRESS(expenses_max_row, COLUMN())))} -> 0 | W58: {=SUM(INDIRECT(ADDRESS(expenses_min_row, COLUMN()) & ":" & ADDRESS(expenses_max_row, COLUMN())))} -> 0 | X58: {=SUM(INDIRECT(ADDRESS(expenses_min_row, COLUMN()) & ":" & ADDRESS(expenses_max_row, COLUMN())))} -> 0 | Y58: {=SUM(INDIRECT(ADDRESS(expenses_min_row, COLUMN()) & ":" & ADDRESS(expenses_max_row, COLUMN())))} -> 0 | Z58: {=SUM(INDIRECT(ADDRESS(expenses_min_row, COLUMN()) & ":" & ADDRESS(expenses_max_row, COLUMN())))} -> 0 | ... AE58: {=SUM(INDIRECT(ADDRESS(expenses_min_row, COLUMN()) & ":" & ADDRESS(expenses_max_row, COLUMN())))} -> 0 | AG58: {=SUM(INDIRECT(ADDRESS(expenses_min_row, COLUMN()) & ":" & ADDRESS(expenses_max_row, COLUMN())))} -> 0 | AH58: {=SUM(INDIRECT(ADDRESS(expenses_min_row, COLUMN()) & ":" & ADDRESS(expenses_max_row, COLUMN())))} -> 0 | AI58: {=SUM(INDIRECT(ADDRESS(expenses_min_row, COLUMN()) & ":" & ADDRESS(expenses_max_row, COLUMN())))} -> 0 | AJ58: {=SUM(INDIRECT(ADDRESS(expenses_min_row, COLUMN()) & ":" & ADDRESS(expenses_max_row, COLUMN())))} -> 0 | AK58: {=SUM(INDIRECT(ADDRESS(expenses_min_row, COLUMN()) & ":" & ADDRESS(expenses_max_row, COLUMN())))} -> 0 | AL58: {=SUM(INDIRECT(ADDRESS(expenses_min_row, COLUMN()) & ":" & ADDRESS(expenses_max_row, COLUMN())))} -> 0 | AM58: {=SUM(INDIRECT(ADDRESS(expenses_min_row, COLUMN()) & ":" & ADDRESS(expenses_max_row, COLUMN())))} -> 0 | AN58: {=SUM(INDIRECT(ADDRESS(expenses_min_row, COLUMN()) & ":" & ADDRESS(expenses_max_row, COLUMN())))} -> 0 | ... AS58: {=SUM(INDIRECT(ADDRESS(expenses_min_row, COLUMN()) & ":" & ADDRESS(expenses_max_row, COLUMN())))} -> 0 | AU58: {=SUM(INDIRECT(ADDRESS(expenses_min_row, COLUMN()) & ":" & ADDRESS(expenses_max_row, COLUMN())))} -> 0 | AV58: {=SUM(INDIRECT(ADDRESS(expenses_min_row, COLUMN()) & ":" & ADDRESS(expenses_max_row, COLUMN())))} -> 0 | AW58: {=SUM(INDIRECT(ADDRESS(expenses_min_row, COLUMN()) & ":" & ADDRESS(expenses_max_row, COLUMN())))} -> 0 | AX58: {=SUM(INDIRECT(ADDRESS(expenses_min_row, COLUMN()) & ":" & ADDRESS(expenses_max_row, COLUMN())))} -> 0 | AY58: {=SUM(INDIRECT(ADDRESS(expenses_min_row, COLUMN()) & ":" & ADDRESS(expenses_max_row, COLUMN())))} -> 0 | AZ58: {=SUM(INDIRECT(ADDRESS(expenses_min_row, COLUMN()) & ":" & ADDRESS(expenses_max_row, COLUMN())))} -> 0 | BA58: {=SUM(INDIRECT(ADDRESS(expenses_min_row, COLUMN()) & ":" & ADDRESS(expenses_max_row, COLUMN())))} -> 0 | BB58: {=SUM(INDIRECT(ADDRESS(expenses_min_row, COLUMN()) & ":" & ADDRESS(expenses_max_row, COLUMN())))} -> 0 | ... BG58: {=SUM(INDIRECT(ADDRESS(expenses_min_row, COLUMN()) & ":" & ADDRESS(expenses_max_row, COLUMN())))} -> 0 | BI58: {=SUM(INDIRECT(ADDRESS(expenses_min_row, COLUMN()) & ":" & ADDRESS(expenses_max_row, COLUMN())))} -> 0 | BJ58: {=SUM(INDIRECT(ADDRESS(expenses_min_row, COLUMN()) & ":" & ADDRESS(expenses_max_row, COLUMN())))} -> 0 | BK58: {=SUM(INDIRECT(ADDRESS(expenses_min_row, COLUMN()) & ":" & ADDRESS(expenses_max_row, COLUMN())))} -> 0 | BL58: {=SUM(INDIRECT(ADDRESS(expenses_min_row, COLUMN()) & ":" & ADDRESS(expenses_max_row, COLUMN())))} -> 0 | BM58: {=SUM(INDIRECT(ADDRESS(expenses_min_row, COLUMN()) & ":" & ADDRESS(expenses_max_row, COLUMN())))} -> 0 | BN58: {=SUM(INDIRECT(ADDRESS(expenses_min_row, COLUMN()) & ":" & ADDRESS(expenses_max_row, COLUMN())))} -> 0 | BO58: {=SUM(INDIRECT(ADDRESS(expenses_min_row, COLUMN()) & ":" & ADDRESS(expenses_max_row, COLUMN())))} -> 0 | BP58: {=SUM(INDIRECT(ADDRESS(expenses_min_row, COLUMN()) & ":" & ADDRESS(expenses_max_row, COLUMN())))} -> 0 | ... BU58: {=SUM(INDIRECT(ADDRESS(expenses_min_row, COLUMN()) & ":" & ADDRESS(expenses_max_row, COLUMN())))} -> 0 | BW58: {=SUM(INDIRECT(ADDRESS(expenses_min_row, COLUMN()) & ":" & ADDRESS(expenses_max_row, COLUMN())))} -> 0 | BX58: {=SUM(INDIRECT(ADDRESS(expenses_min_row, COLUMN()) & ":" & ADDRESS(expenses_max_row, COLUMN())))} -> 0 | BY58: {=SUM(INDIRECT(ADDRESS(expenses_min_row, COLUMN()) & ":" & ADDRESS(expenses_max_row, COLUMN())))} -> 0 | BZ58: {=SUM(INDIRECT(ADDRESS(expenses_min_row, COLUMN()) & ":" & ADDRESS(expenses_max_row, COLUMN())))} -> 0 | CA58: {=SUM(INDIRECT(ADDRESS(expenses_min_row, COLUMN()) & ":" & ADDRESS(expenses_max_row, COLUMN())))} -> 0 | CB58: {=SUM(INDIRECT(ADDRESS(expenses_min_row, COLUMN()) & ":" & ADDRESS(expenses_max_row, COLUMN())))} -> 0 | CC58: {=SUM(INDIRECT(ADDRESS(expenses_min_row, COLUMN()) & ":" & ADDRESS(expenses_max_row, COLUMN())))} -> 0 | CD58: {=SUM(INDIRECT(ADDRESS(expenses_min_row, COLUMN()) & ":" & ADDRESS(expenses_max_row, COLUMN())))} -> 0 | ... CI58: {=SUM(INDIRECT(ADDRESS(expenses_min_row, COLUMN()) & ":" & ADDRESS(expenses_max_row, COLUMN())))} -> 0 | CK58: {=SUM(INDIRECT(ADDRESS(expenses_min_row, COLUMN()) & ":" & ADDRESS(expenses_max_row, COLUMN())))} -> 0 | CL58: {=SUM(INDIRECT(ADDRESS(expenses_min_row, COLUMN()) & ":" & ADDRESS(expenses_max_row, COLUMN())))} -> 0 | CM58: {=SUM(INDIRECT(ADDRESS(expenses_min_row, COLUMN()) & ":" & ADDRESS(expenses_max_row, COLUMN())))} -> 0 | CN58: {=SUM(INDIRECT(ADDRESS(expenses_min_row, COLUMN()) & ":" & ADDRESS(expenses_max_row, COLUMN())))} -> 0 | CO58: {=SUM(INDIRECT(ADDRESS(expenses_min_row, COLUMN()) & ":" & ADDRESS(expenses_max_row, COLUMN())))} -> 0 | CP58: {=SUM(INDIRECT(ADDRESS(expenses_min_row, COLUMN()) & ":" & ADDRESS(expenses_max_row, COLUMN())))} -> 0 | CQ58: {=SUM(INDIRECT(ADDRESS(expenses_min_row, COLUMN()) & ":" & ADDRESS(expenses_max_row, COLUMN())))} -> 0 | CR58: {=SUM(INDIRECT(ADDRESS(expenses_min_row, COLUMN()) & ":" & ADDRESS(expenses_max_row, COLUMN())))} -> 0 | ... CW58: {=SUM(INDIRECT(ADDRESS(expenses_min_row, COLUMN()) & ":" & ADDRESS(expenses_max_row, COLUMN())))} -> 0 | CY58: {=SUM(INDIRECT(ADDRESS(expenses_min_row, COLUMN()) & ":" & ADDRESS(expenses_max_row, COLUMN())))} -> 0 | CZ58: {=SUM(INDIRECT(ADDRESS(expenses_min_row, COLUMN()) & ":" & ADDRESS(expenses_max_row, COLUMN())))} -> 0 | DA58: {=SUM(INDIRECT(ADDRESS(expenses_min_row, COLUMN()) & ":" & ADDRESS(expenses_max_row, COLUMN())))} -> 0 | DB58: {=SUM(INDIRECT(ADDRESS(expenses_min_row, COLUMN()) & ":" & ADDRESS(expenses_max_row, COLUMN())))} -> 0 | DC58: {=SUM(INDIRECT(ADDRESS(expenses_min_row, COLUMN()) & ":" & ADDRESS(expenses_max_row, COLUMN())))} -> 0 | DD58: {=SUM(INDIRECT(ADDRESS(expenses_min_row, COLUMN()) & ":" & ADDRESS(expenses_max_row, COLUMN())))} -> 0 | DE58: {=SUM(INDIRECT(ADDRESS(expenses_min_row, COLUMN()) & ":" & ADDRESS(expenses_max_row, COLUMN())))} -> 0 | DF58: {=SUM(INDIRECT(ADDRESS(expenses_min_row, COLUMN()) & ":" & ADDRESS(expenses_max_row, COLUMN())))} -> 0 | ... DK58: {=SUM(INDIRECT(ADDRESS(expenses_min_row, COLUMN()) & ":" & ADDRESS(expenses_max_row, COLUMN())))} -> 0 | DM58: {=SUM(INDIRECT(ADDRESS(expenses_min_row, COLUMN()) & ":" & ADDRESS(expenses_max_row, COLUMN())))} -> 0 | DN58: {=SUM(INDIRECT(ADDRESS(expenses_min_row, COLUMN()) & ":" & ADDRESS(expenses_max_row, COLUMN())))} -> 0 | DO58: {=SUM(INDIRECT(ADDRESS(expenses_min_row, COLUMN()) & ":" & ADDRESS(expenses_max_row, COLUMN())))} -> 0 | DP58: {=SUM(INDIRECT(ADDRESS(expenses_min_row, COLUMN()) & ":" & ADDRESS(expenses_max_row, COLUMN())))} -> 0 | DQ58: {=SUM(INDIRECT(ADDRESS(expenses_min_row, COLUMN()) & ":" & ADDRESS(expenses_max_row, COLUMN())))} -> 0 | DR58: {=SUM(INDIRECT(ADDRESS(expenses_min_row, COLUMN()) & ":" & ADDRESS(expenses_max_row, COLUMN())))} -> 0 | DS58: {=SUM(INDIRECT(ADDRESS(expenses_min_row, COLUMN()) & ":" & ADDRESS(expenses_max_row, COLUMN())))} -> 0 | DT58: {=SUM(INDIRECT(ADDRESS(expenses_min_row, COLUMN()) & ":" & ADDRESS(expenses_max_row, COLUMN())))} -> 0 | ... DY58: {=SUM(INDIRECT(ADDRESS(expenses_min_row, COLUMN()) & ":" & ADDRESS(expenses_max_row, COLUMN())))} -> 0 | EA58: {=SUM(INDIRECT(ADDRESS(expenses_min_row, COLUMN()) & ":" & ADDRESS(expenses_max_row, COLUMN())))} -> 0 | EB58: {=SUM(INDIRECT(ADDRESS(expenses_min_row, COLUMN()) & ":" & ADDRESS(expenses_max_row, COLUMN())))} -> 0 | EC58: {=SUM(INDIRECT(ADDRESS(expenses_min_row, COLUMN()) & ":" & ADDRESS(expenses_max_row, COLUMN())))} -> 0 | ED58: {=SUM(INDIRECT(ADDRESS(expenses_min_row, COLUMN()) & ":" & ADDRESS(expenses_max_row, COLUMN())))} -> 0 | EE58: {=SUM(INDIRECT(ADDRESS(expenses_min_row, COLUMN()) & ":" & ADDRESS(expenses_max_row, COLUMN())))} -> 0 | EF58: {=SUM(INDIRECT(ADDRESS(expenses_min_row, COLUMN()) & ":" & ADDRESS(expenses_max_row, COLUMN())))} -> 0 | EG58: {=SUM(INDIRECT(ADDRESS(expenses_min_row, COLUMN()) & ":" & ADDRESS(expenses_max_row, COLUMN())))} -> 0 | EH58: {=SUM(INDIRECT(ADDRESS(expenses_min_row, COLUMN()) & ":" & ADDRESS(expenses_max_row, COLUMN())))} -> 0 | ... EM58: {=SUM(INDIRECT(ADDRESS(expenses_min_row, COLUMN()) & ":" & ADDRESS(expenses_max_row, COLUMN())))} -> 0
C60: Savings | E60: =DATE(E$5,1,1) -> 44562 | F60: =DATE(E$5,2,1) -> 44593 | G60: =DATE(E$5,3,1) -> 44621 | H60: =DATE(E$5,4,1) -> 44652 | I60: =DATE(E$5,5,1) -> 44682 | J60: =DATE(E$5,6,1) -> 44713 | K60: =DATE(E$5,7,1) -> 44743 | L60: =DATE(E$5,8,1) -> 44774 | M60: =DATE(E$5,9,1) -> 44805 | N60: =DATE(E$5,10,1) -> 44835 | O60: =DATE(E$5,11,1) -> 44866 | P60: =DATE(E$5,12,1) -> 44896 | Q60: =E$5 -> 2022 | S60: =DATE(S$5,1,1) -> 44927 | T60: =DATE(S$5,2,1) -> 44958 | U60: =DATE(S$5,3,1) -> 44986 | V60: =DATE(S$5,4,1) -> 45017 | W60: =DATE(S$5,5,1) -> 45047 | X60: =DATE(S$5,6,1) -> 45078 | Y60: =DATE(S$5,7,1) -> 45108 | Z60: =DATE(S$5,8,1) -> 45139 | AA60: =DATE(S$5,9,1) -> 45170 | AB60: =DATE(S$5,10,1) -> 45200 | AC60: =DATE(S$5,11,1) -> 45231 | AD60: =DATE(S$5,12,1) -> 45261 | AE60: =S$5 -> 2023 | AG60: =DATE(AG$5,1,1) -> 45292 | AH60: =DATE(AG$5,2,1) -> 45323 | AI60: =DATE(AG$5,3,1) -> 45352 | AJ60: =DATE(AG$5,4,1) -> 45383 | AK60: =DATE(AG$5,5,1) -> 45413 | AL60: =DATE(AG$5,6,1) -> 45444 | AM60: =DATE(AG$5,7,1) -> 45474 | AN60: =DATE(AG$5,8,1) -> 45505 | AO60: =DATE(AG$5,9,1) -> 45536 | AP60: =DATE(AG$5,10,1) -> 45566 | AQ60: =DATE(AG$5,11,1) -> 45597 | AR60: =DATE(AG$5,12,1) -> 45627 | AS60: =AG$5 -> 2024 | AU60: =DATE(AU$5,1,1) -> 45658 | AV60: =DATE(AU$5,2,1) -> 45689 | AW60: =DATE(AU$5,3,1) -> 45717 | AX60: =DATE(AU$5,4,1) -> 45748 | AY60: =DATE(AU$5,5,1) -> 45778 | AZ60: =DATE(AU$5,6,1) -> 45809 | BA60: =DATE(AU$5,7,1) -> 45839 | BB60: =DATE(AU$5,8,1) -> 45870 | BC60: =DATE(AU$5,9,1) -> 45901 | BD60: =DATE(AU$5,10,1) -> 45931 | BE60: =DATE(AU$5,11,1) -> 45962 | BF60: =DATE(AU$5,12,1) -> 45992 | BG60: =AU$5 -> 2025 | BI60: =DATE(BI$5,1,1) -> 46023 | BJ60: =DATE(BI$5,2,1) -> 46054 | BK60: =DATE(BI$5,3,1) -> 46082 | BL60: =DATE(BI$5,4,1) -> 46113 | BM60: =DATE(BI$5,5,1) -> 46143 | BN60: =DATE(BI$5,6,1) -> 46174 | BO60: =DATE(BI$5,7,1) -> 46204 | BP60: =DATE(BI$5,8,1) -> 46235 | BQ60: =DATE(BI$5,9,1) -> 46266 | BR60: =DATE(BI$5,10,1) -> 46296 | BS60: =DATE(BI$5,11,1) -> 46327 | BT60: =DATE(BI$5,12,1) -> 46357 | BU60: =BI$5 -> 2026 | BW60: =DATE(BW$5,1,1) -> 46388 | BX60: =DATE(BW$5,2,1) -> 46419 | BY60: =DATE(BW$5,3,1) -> 46447 | BZ60: =DATE(BW$5,4,1) -> 46478 | CA60: =DATE(BW$5,5,1) -> 46508 | CB60: =DATE(BW$5,6,1) -> 46539 | CC60: =DATE(BW$5,7,1) -> 46569 | CD60: =DATE(BW$5,8,1) -> 46600 | CE60: =DATE(BW$5,9,1) -> 46631 | CF60: =DATE(BW$5,10,1) -> 46661 | CG60: =DATE(BW$5,11,1) -> 46692 | CH60: =DATE(BW$5,12,1) -> 46722 | CI60: =BW$5 -> 2027 | CK60: =DATE(CK$5,1,1) -> 46753 | CL60: =DATE(CK$5,2,1) -> 46784 | CM60: =DATE(CK$5,3,1) -> 46813 | CN60: =DATE(CK$5,4,1) -> 46844 | CO60: =DATE(CK$5,5,1) -> 46874 | CP60: =DATE(CK$5,6,1) -> 46905 | CQ60: =DATE(CK$5,7,1) -> 46935 | CR60: =DATE(CK$5,8,1) -> 46966 | CS60: =DATE(CK$5,9,1) -> 46997 | CT60: =DATE(CK$5,10,1) -> 47027 | CU60: =DATE(CK$5,11,1) -> 47058 | CV60: =DATE(CK$5,12,1) -> 47088 | CW60: =CK$5 -> 2028 | CY60: =DATE(CY$5,1,1) -> 47119 | CZ60: =DATE(CY$5,2,1) -> 47150 | DA60: =DATE(CY$5,3,1) -> 47178 | DB60: =DATE(CY$5,4,1) -> 47209 | DC60: =DATE(CY$5,5,1) -> 47239 | DD60: =DATE(CY$5,6,1) -> 47270 | DE60: =DATE(CY$5,7,1) -> 47300 | DF60: =DATE(CY$5,8,1) -> 47331 | DG60: =DATE(CY$5,9,1) -> 47362 | DH60: =DATE(CY$5,10,1) -> 47392 | DI60: =DATE(CY$5,11,1) -> 47423 | DJ60: =DATE(CY$5,12,1) -> 47453 | DK60: =CY$5 -> 2029 | DM60: =DATE(DM$5,1,1) -> 47484 | DN60: =DATE(DM$5,2,1) -> 47515 | DO60: =DATE(DM$5,3,1) -> 47543 | DP60: =DATE(DM$5,4,1) -> 47574 | DQ60: =DATE(DM$5,5,1) -> 47604 | DR60: =DATE(DM$5,6,1) -> 47635 | DS60: =DATE(DM$5,7,1) -> 47665 | DT60: =DATE(DM$5,8,1) -> 47696 | DU60: =DATE(DM$5,9,1) -> 47727 | DV60: =DATE(DM$5,10,1) -> 47757 | DW60: =DATE(DM$5,11,1) -> 47788 | DX60: =DATE(DM$5,12,1) -> 47818 | DY60: =DM$5 -> 2030 | EA60: =DATE(EA$5,1,1) -> 47849 | EB60: =DATE(EA$5,2,1) -> 47880 | EC60: =DATE(EA$5,3,1) -> 47908 | ED60: =DATE(EA$5,4,1) -> 47939 | EE60: =DATE(EA$5,5,1) -> 47969 | EF60: =DATE(EA$5,6,1) -> 48000 | EG60: =DATE(EA$5,7,1) -> 48030 | EH60: =DATE(EA$5,8,1) -> 48061 | EI60: =DATE(EA$5,9,1) -> 48092 | EJ60: =DATE(EA$5,10,1) -> 48122 | EK60: =DATE(EA$5,11,1) -> 48153 | EL60: =DATE(EA$5,12,1) -> 48183 | EM60: =EA$5 -> 2031
C61: Enter Savings Category… | Q61: =SUM(E61:P61) -> 0 | AE61: =SUM(S61:AD61) -> 0 | AS61: =SUM(AG61:AR61) -> 0 | BG61: =SUM(AU61:BF61) -> 0 | BU61: =SUM(BI61:BT61) -> 0 | CI61: =SUM(BW61:CH61) -> 0 | CW61: =SUM(CK61:CV61) -> 0 | DK61: =SUM(CY61:DJ61) -> 0 | DY61: =SUM(DM61:DX61) -> 0 | EM61: =SUM(EA61:EL61) -> 0
C62: Enter Savings Category… | Q62: =SUM(E62:P62) -> 0 | AE62: =SUM(S62:AD62) -> 0 | AS62: =SUM(AG62:AR62) -> 0 | BG62: =SUM(AU62:BF62) -> 0 | BU62: =SUM(BI62:BT62) -> 0 | CI62: =SUM(BW62:CH62) -> 0 | CW62: =SUM(CK62:CV62) -> 0 | DK62: =SUM(CY62:DJ62) -> 0 | DY62: =SUM(DM62:DX62) -> 0 | EM62: =SUM(EA62:EL62) -> 0
C63: Enter Savings Category… | Q63: =SUM(E63:P63) -> 0 | AE63: =SUM(S63:AD63) -> 0 | AS63: =SUM(AG63:AR63) -> 0 | BG63: =SUM(AU63:BF63) -> 0 | BU63: =SUM(BI63:BT63) -> 0 | CI63: =SUM(BW63:CH63) -> 0 | CW63: =SUM(CK63:CV63) -> 0 | DK63: =SUM(CY63:DJ63) -> 0 | DY63: =SUM(DM63:DX63) -> 0 | EM63: =SUM(EA63:EL63) -> 0
C64: Enter Savings Category… | Q64: =SUM(E64:P64) -> 0 | AE64: =SUM(S64:AD64) -> 0 | AS64: =SUM(AG64:AR64) -> 0 | BG64: =SUM(AU64:BF64) -> 0 | BU64: =SUM(BI64:BT64) -> 0 | CI64: =SUM(BW64:CH64) -> 0 | CW64: =SUM(CK64:CV64) -> 0 | DK64: =SUM(CY64:DJ64) -> 0 | DY64: =SUM(DM64:DX64) -> 0 | EM64: =SUM(EA64:EL64) -> 0
C65: Enter Savings Category… | Q65: =SUM(E65:P65) -> 0 | AE65: =SUM(S65:AD65) -> 0 | AS65: =SUM(AG65:AR65) -> 0 | BG65: =SUM(AU65:BF65) -> 0 | BU65: =SUM(BI65:BT65) -> 0 | CI65: =SUM(BW65:CH65) -> 0 | CW65: =SUM(CK65:CV65) -> 0 | DK65: =SUM(CY65:DJ65) -> 0 | DY65: =SUM(DM65:DX65) -> 0 | EM65: =SUM(EA65:EL65) -> 0
C66: Enter Savings Category… | Q66: =SUM(E66:P66) -> 0 | AE66: =SUM(S66:AD66) -> 0 | AS66: =SUM(AG66:AR66) -> 0 | BG66: =SUM(AU66:BF66) -> 0 | BU66: =SUM(BI66:BT66) -> 0 | CI66: =SUM(BW66:CH66) -> 0 | CW66: =SUM(CK66:CV66) -> 0 | DK66: =SUM(CY66:DJ66) -> 0 | DY66: =SUM(DM66:DX66) -> 0 | EM66: =SUM(EA66:EL66) -> 0
C67: Enter Savings Category… | Q67: =SUM(E67:P67) -> 0 | AE67: =SUM(S67:AD67) -> 0 | AS67: =SUM(AG67:AR67) -> 0 | BG67: =SUM(AU67:BF67) -> 0 | BU67: =SUM(BI67:BT67) -> 0 | CI67: =SUM(BW67:CH67) -> 0 | CW67: =SUM(CK67:CV67) -> 0 | DK67: =SUM(CY67:DJ67) -> 0 | DY67: =SUM(DM67:DX67) -> 0 | EM67: =SUM(EA67:EL67) -> 0
C68: Enter Savings Category… | Q68: =SUM(E68:P68) -> 0 | AE68: =SUM(S68:AD68) -> 0 | AS68: =SUM(AG68:AR68) -> 0 | BG68: =SUM(AU68:BF68) -> 0 | BU68: =SUM(BI68:BT68) -> 0 | CI68: =SUM(BW68:CH68) -> 0 | CW68: =SUM(CK68:CV68) -> 0 | DK68: =SUM(CY68:DJ68) -> 0 | DY68: =SUM(DM68:DX68) -> 0 | EM68: =SUM(EA68:EL68) -> 0
...

Sheet Budget Tracking
B2: Budget Tracking
C11: Date | D11: Type | E11: Category | F11: Amount | G11: Details | H11: Balance | I11: Effective Date
H12: {=IFERROR(SUMPRODUCT(Tracking[Amount], --(Tracking[Date]<=Tracking[[#This Row],[Date]]), (Tracking[Type]<>"Income") * (-1) + (Tracking[Type]="Income")), "-")} -> - | I12: =IF(AND(Tracking[[#This Row],[Type]]="Income", shift_late_income_status="Active", DAY(Tracking[[#This Row],[Date]])>=shift_late_income_starting_day), DATE(YEAR(Tracking[[#This Row],[Date]]), MONTH(Tracking[[#This Row],[Date]])+1, 1), Tracking[[#This Row],[Date]]) -> 0

Sheet Budget Dashboard
B2: Budget Dashboard
AQ5: Year
AN6: Select the year to view ➜ | AQ6: Current Year
AQ8: Period
AN9: Select the period to view ➜ | AQ9: Current Month
Y11: ="Breakdown - " & IF(selected_period="Total Year", selected_year & " (Total Year)", selected_period_display & " " & selected_year) -> Breakdown - February 2025 | AF11: ="Summary - " & IF(selected_period="Total Year", selected_year & " (Total Year)", selected_period_display & " " & selected_year) -> Summary - February 2025
C12: row_id | D12: header_row_id | E12: is_header | F12: is_cat | G12: is_total | H12: is_empty | I12: type | J12: item | K12: tracked | L12: budget | M12: sort_min_row | N12: sort_max_row | O12: tracked_range | P12: tracked_rank | Q12: budget_range | R12: budget_rank | S12: comb_rank | T12: comb_rank_range | U12: comb_rank_norm | V12: comb_rank_norm_run_range | W12: comb_rank_unique | X12: sorted_row_id [Lookup]
C13: {=income_header_row} -> 9 | D13: =IF(is_header, row_id, IF(NOT(is_empty), D12,-1)) -> 9 | E13: {=1*OR(row_id=income_header_row, row_id=expenses_header_row, row_id=savings_header_row)} -> 1 | F13: =1*NOT(OR(is_header, is_total, is_empty)) -> 0 | G13: {=1*OR(row_id=income_total_row, row_id=expenses_total_row, row_id=savings_total_row)} -> 0 | H13: =1*OR(row_id="/1", row_id="/2", row_id=-1) -> 0 | I13: {=IFERROR(INDEX('Budget Planning'!$C:$C, header_row_id),"")} -> Income | J13: {=IFERROR(INDEX('Budget Planning'!$C:$C, row_id),"")} -> Income | K13: {=IF(OR(is_header, is_empty), "", IF(is_total, IF(selected_period="Total Year", SUM( Tracking[Amount] * (Tracking[Type]=type) * (YEAR(Tracking[Effective Date])=selected_year) ), SUM( Tracking[Amount] * (Tracking[Type]=type) * (YEAR(Tracking[Effective Date])=selected_year) * (MONTH(Tracking[Effective Date])=selected_period) )), IF(selected_period="Total Year", SUM( Tracking[Amount] * (Tracking[Type]=type) * (Tracking[Category]=item) * (YEAR(Tracking[Effective Date])=selected_year) ), SUM( Tracking[Amount] * (Tracking[Type]=type) * (Tracking[Category]=item) * (YEAR(Tracking[Effective Date])=selected_year) * (MONTH(Tracking[Effective Date])=selected_period) )) ) )} | L13: {=IF(OR(is_header, is_empty), "", INDEX('Budget Planning'!$E:$EM, row_id, MATCH(IF(selected_period="Total Year", selected_year, DATE(selected_year, selected_period, 1)), 'Budget Planning'!$E$9:$EM$9, 0) ))} | M13: {=IF(is_cat, IF(header_row_id=income_header_row, MATCH(income_min_row, $C:$C, 0), IF(header_row_id=expenses_header_row, MATCH(expenses_min_row, $C:$C, 0), IF(header_row_id=savings_header_row, MATCH(savings_min_row, $C:$C, 0),""))), "")} | N13: {=IF(is_cat, IF(header_row_id=income_header_row, MATCH(income_max_row, $C:$C, 0), IF(header_row_id=expenses_header_row, MATCH(expenses_max_row, $C:$C, 0), IF(header_row_id=savings_header_row, MATCH(savings_max_row, $C:$C, 0),""))), "")} | O13: =IF(is_cat, ADDRESS(sort_min_row, COLUMN(tracked)) & ":" & ADDRESS(sort_max_row, COLUMN(tracked)), "") | P13: =IF(is_cat, RANK(tracked, INDIRECT(tracked_range), 0), "") | Q13: =IF(is_cat, ADDRESS(sort_min_row, COLUMN(budget)) & ":" & ADDRESS(sort_max_row, COLUMN(budget)), "") | R13: =IF(is_cat, RANK(budget, INDIRECT(budget_range), 0), "") | S13: =IF(is_cat, _xlfn.NUMBERVALUE( tracked_rank & IF(LEN(budget_rank)=1, "0", "") & budget_rank), "") | T13: =IF(is_cat, ADDRESS(sort_min_row, COLUMN(comb_rank)) & ":" & ADDRESS(sort_max_row, COLUMN(comb_rank)), "") | U13: =IF(is_cat, RANK(comb_rank, INDIRECT(comb_rank_range), 1), "") | V13: =IF(is_cat, ADDRESS(sort_min_row, COLUMN(comb_rank_norm)) & ":" & ADDRESS(ROW(), COLUMN(comb_rank_norm)), "") | W13: =IF(is_cat, comb_rank_norm + COUNTIF(INDIRECT(comb_rank_norm_run_range), comb_rank_norm)-1, "") | X13: =IF(is_cat, header_row_id + comb_rank_unique, row_id) -> 9 | Y13: =IF(is_empty, "", INDEX($J:$J, MATCH(row_id, $X:$X, 0))) -> Income | Z13: =IF(is_empty, "", IF(is_header, "Tracked", INDEX($K:$K, MATCH(row_id, $X:$X, 0)))) -> Tracked | AA13: =IF(is_empty, "", IF(is_header, "Budget", INDEX($L:$L, MATCH(row_id, $X:$X, 0)))) -> Budget | AB13: =IF(is_empty, "", IF(is_header, "% Compl.", IFERROR(out_tracked / out_budget, "-"))) -> % Compl. | AC13: =IF(is_empty, "", IF(is_header, "Remaining", IF(out_budget - out_tracked > 0, out_budget - out_tracked, 0))) -> Remaining | AD13: =IF(is_empty, "", IF(is_header, "Excess", IF(out_budget - out_tracked < 0, out_tracked - out_budget, 0))) -> Excess
